<?xml version="1.0"?>
<!--
  Robot: robot_simple_imu
  Generated by: LinkForge v1.3.4
  https://github.com/arounamounchili/linkforge
  Date: 2026-05-26 16:34:21
-->
<robot name="robot_simple_imu">
  <!-- Materials -->
  <material name="_0_001">
    <color rgba="0.01281 0.048622 0.075361 0.5" />
  </material>
  <!-- Links -->
  <link name="hub">
    <inertial>
      <mass value="0.1498" />
      <inertia ixx="0.0003996651" ixy="-7.764129e-08" ixz="-3.0062797e-06" iyy="0.0007836248" iyz="-1.4107684e-08" izz="0.0010106043" />
    </inertial>
    <visual>
      <origin xyz="0 0 0.04" rpy="0 0 0" />
      <geometry>
        <mesh filename="meshes/prime_hub_visual.obj" />
      </geometry>
    </visual>
  </link>
  <link name="world">
    <inertial>
      <mass value="100" />
      <inertia ixx="8.336667" ixy="0" ixz="0" iyy="8.336667" iyz="0" izz="16.666667" />
    </inertial>
    <visual>
      <origin xyz="0 0 -0.01" rpy="0 0 0" />
      <geometry>
        <box size="1 1 0.02" />
      </geometry>
      <material name="_0_001" />
    </visual>
  </link>
  <!-- Joints -->
  <joint name="hub_joint" type="floating">
    <parent link="world" />
    <child link="hub" />
  </joint>
</robot>