<?xml version="1.0"?>
<!--
  Robot: robot_fancy_clock
  Generated by: LinkForge v1.3.4
  https://github.com/arounamounchili/linkforge
  Date: 2026-06-12 16:52:02
-->
<robot name="robot_fancy_clock">
  <!-- Materials -->
  <material name="_0_001">
    <color rgba="0.01281 0.048622 0.075361 0.5" />
  </material>
  <!-- Links -->
  <link name="base">
    <inertial>
      <mass value="0.2522" />
      <inertia ixx="0.004595966" ixy="1.5908203e-05" ixz="-0.0001171288" iyy="0.003955696" iyz="2.9241957e-05" izz="0.0024333475" />
    </inertial>
    <visual>
      <origin xyz="0 0 0.182375" rpy="0 0 0" />
      <geometry>
        <mesh filename="meshes/base_visual.obj" />
      </geometry>
    </visual>
  </link>
  <link name="clock">
    <inertial>
      <mass value="0.0042" />
      <inertia ixx="2.9608782e-05" ixy="1.5979884e-11" ixz="1.0643271e-05" iyy="4.1455205e-05" iyz="-4.0351056e-11" izz="1.2443532e-05" />
    </inertial>
    <visual>
      <origin xyz="-0.1 -0.000002 0.412877" rpy="0 0 0" />
      <geometry>
        <mesh filename="meshes/clock_visual.obj" />
      </geometry>
    </visual>
  </link>
  <link name="world">
    <inertial>
      <mass value="100" />
      <inertia ixx="8.336667" ixy="0" ixz="0" iyy="8.336667" iyz="0" izz="16.666667" />
    </inertial>
    <visual>
      <geometry>
        <box size="1 1 0.02" />
      </geometry>
      <material name="_0_001" />
    </visual>
  </link>
  <!-- Joints -->
  <joint name="base_joint" type="floating">
    <parent link="world" />
    <child link="base" />
  </joint>
  <joint name="clock_joint" type="revolute">
    <parent link="base" />
    <child link="clock" />
    <axis xyz="1 0 0" />
    <limit effort="10" velocity="1" lower="-3.141593" upper="3.141593" />
  </joint>
</robot>